<?xml version="1.0" ?>
<!-- =================================================================================== -->
<!-- |    This document was autogenerated by xacro from /home/shyjo/catkin_ws/src/diffrential_picker_robot/urdf/finaldesign.xacro | -->
<!-- |    EDITING THIS FILE BY HAND IS NOT RECOMMENDED                                 | -->
<!-- =================================================================================== -->
<robot name="finaldesign">
    <material name="silver">
        <color rgba="0.700 0.700 0.700 1.000" />
    </material>
    <transmission name="Revolute 1_tran">
        <type>transmission_interface/SimpleTransmission</type>
        <joint name="Revolute_1">
            <hardwareInterface>hardware_interface/EffortJointInterface</hardwareInterface>
        </joint>
        <actuator name="Revolute 1_actr">
            <hardwareInterface>hardware_interface/EffortJointInterface</hardwareInterface>
            <mechanicalReduction>1</mechanicalReduction>
        </actuator>
    </transmission>
    <transmission name="Revolute 2_tran">
        <type>transmission_interface/SimpleTransmission</type>
        <joint name="Revolute_2">
            <hardwareInterface>hardware_interface/EffortJointInterface</hardwareInterface>
        </joint>
        <actuator name="Revolute 2_actr">
            <hardwareInterface>hardware_interface/EffortJointInterface</hardwareInterface>
            <mechanicalReduction>1</mechanicalReduction>
        </actuator>
    </transmission>
    <transmission name="Revolute 4_tran">
        <type>transmission_interface/SimpleTransmission</type>
        <joint name="Revolute_4">
            <hardwareInterface>hardware_interface/EffortJointInterface</hardwareInterface>
        </joint>
        <actuator name="Revolute 4_actr">
            <hardwareInterface>hardware_interface/EffortJointInterface</hardwareInterface>
            <mechanicalReduction>1</mechanicalReduction>
        </actuator>
    </transmission>
    <transmission name="Revolute 7_tran">
        <type>transmission_interface/SimpleTransmission</type>
        <joint name="Revolute_7">
            <hardwareInterface>hardware_interface/EffortJointInterface</hardwareInterface>
        </joint>
        <actuator name="Revolute 7_actr">
            <hardwareInterface>hardware_interface/EffortJointInterface</hardwareInterface>
            <mechanicalReduction>1</mechanicalReduction>
        </actuator>
    </transmission>
    <transmission name="Slider 8_tran">
        <type>transmission_interface/SimpleTransmission</type>
        <joint name="Slider_8">
            <hardwareInterface>hardware_interface/EffortJointInterface</hardwareInterface>
        </joint>
        <actuator name="Slider 8_actr">
            <hardwareInterface>hardware_interface/EffortJointInterface</hardwareInterface>
            <mechanicalReduction>1</mechanicalReduction>
        </actuator>
    </transmission>
    <transmission name="Slider 9_tran">
        <type>transmission_interface/SimpleTransmission</type>
        <joint name="Slider_9">
            <hardwareInterface>hardware_interface/EffortJointInterface</hardwareInterface>
        </joint>
        <actuator name="Slider 9_actr">
            <hardwareInterface>hardware_interface/EffortJointInterface</hardwareInterface>
            <mechanicalReduction>1</mechanicalReduction>
        </actuator>
    </transmission>
    <gazebo>
        <plugin filename="libgazebo_ros_control.so" name="control" />
        <plugin name="gazebo_ros_control" filename="libgazebo_ros_control.so">
            <robotNamespace>/</robotNamespace>
        </plugin>
    </gazebo>
    <gazebo reference="base_link">
        <material>Gazebo/Silver</material>
        <mu1>0.1</mu1>
        <mu2>0.1</mu2>
        <selfCollide>true</selfCollide>
        <gravity>true</gravity>
    </gazebo>
    <gazebo reference="right_wheel_1">
        <material>Gazebo/Silver</material>
        <mu1>1500</mu1>
        <mu2>1500</mu2>
        <selfCollide>true</selfCollide>
    </gazebo>
    <gazebo reference="left_wheel_1">
        <material>Gazebo/Silver</material>
        <mu1>1500</mu1>
        <mu2>1500</mu2>
        <selfCollide>true</selfCollide>
    </gazebo>
    <gazebo reference="Component8_1">
        <material>Gazebo/Silver</material>
        <mu1>0.2</mu1>
        <mu2>0.2</mu2>
        <selfCollide>true</selfCollide>
    </gazebo>
    <gazebo reference="Component2_1">
        <material>Gazebo/Silver</material>
        <mu1>0.2</mu1>
        <mu2>0.2</mu2>
        <selfCollide>true</selfCollide>
    </gazebo>
    <gazebo reference="Component3_1">
        <material>Gazebo/Silver</material>
        <mu1>0.2</mu1>
        <mu2>0.2</mu2>
        <selfCollide>true</selfCollide>
    </gazebo>
    <gazebo reference="Component6_1">
        <material>Gazebo/Silver</material>
        <mu1>0.2</mu1>
        <mu2>0.2</mu2>
        <selfCollide>true</selfCollide>
    </gazebo>
    <gazebo reference="Component7_1">
        <material>Gazebo/Silver</material>
        <mu1>0.2</mu1>
        <mu2>0.2</mu2>
        <selfCollide>true</selfCollide>
    </gazebo>
    <gazebo>
        <plugin filename="libgazebo_ros_diff_drive.so" name="differential_drive_controller">
            <!-- Plugin update rate in Hz -->
            <updateRate>100</updateRate>
            <!-- Name of left joint, defaults to `left_joint` -->
            <leftJoint>Revolute_2</leftJoint>
            <!-- Name of right joint, defaults to `right_joint` -->
            <rightJoint>Revolute_1</rightJoint>
            <!-- The distance from the center of one wheel to the other, in meters, defaults to 0.34 m -->
            <wheelSeparation>0.2</wheelSeparation>
            <!-- Diameter of the wheels, in meters, defaults to 0.15 m -->
            <wheelDiameter>0.1</wheelDiameter>
            <!-- Wheel acceleration, in rad/s^2, defaults to 0.0 rad/s^2 -->
            <wheelAcceleration>1.0</wheelAcceleration>
            <!-- Maximum torque which the wheels can produce, in Nm, defaults to 5 Nm -->
            <wheelTorque>50</wheelTorque>
            <!-- Topic to receive geometry_msgs/Twist message commands, defaults to `cmd_vel` -->
            <commandTopic>cmd_vel</commandTopic>
            <!-- Topic to publish nav_msgs/Odometry messages, defaults to `odom` -->
            <odometryTopic>odom</odometryTopic>
            <!-- Odometry frame, defaults to `odom` -->
            <odometryFrame>odom</odometryFrame>
            <!-- Robot frame to calculate odometry from, defaults to `base_footprint` -->
            <robotBaseFrame>base_link</robotBaseFrame>
            <!-- Odometry source, 0 for ENCODER, 1 for WORLD, defaults to WORLD -->
            <odometrySource>1</odometrySource>
            <!-- Set to true to publish transforms for the wheel links, defaults to false -->
            <publishWheelTF>true</publishWheelTF>
            <!-- Set to true to publish transforms for the odometry, defaults to true -->
            <publishOdom>true</publishOdom>
            <!-- Set to true to publish sensor_msgs/JointState on /joint_states for the wheel joints, defaults to false -->
            <publishWheelJointState>true</publishWheelJointState>
            <!-- Set to true to swap right and left wheels, defaults to true -->
            <legacyMode>false</legacyMode>
        </plugin>
    </gazebo>
    <!-- hokuyo -->
    <gazebo reference="Component8_1">
        <sensor name="head_hokuyo_sensor" type="ray">
            <pose>0 0 0 0 0 0</pose>
            <visualize>true</visualize>
            <update_rate>40</update_rate>
            <ray>
                <scan>
                    <horizontal>
                        <samples>720</samples>
                        <resolution>1</resolution>
                        <min_angle>1.570796</min_angle>
                        <max_angle>4.71</max_angle>
                    </horizontal>
                </scan>
                <range>
                    <min>0.10</min>
                    <max>30.0</max>
                    <resolution>0.01</resolution>
                </range>
                <noise>
                    <type>gaussian</type>
                    <!-- Noise parameters based on published spec for Hokuyo laser
               achieving "+-30mm" accuracy at range < 10m.  A mean of 0.0m and
               stddev of 0.01m will put 99.7% of samples within 0.03m of the true
               reading. -->
                    <mean>0.0</mean>
                    <stddev>0.01</stddev>
                </noise>
            </ray>
            <plugin filename="libgazebo_ros_laser.so" name="gazebo_ros_head_hokuyo_controller">
                <topicName>/scan</topicName>
                <frameName>Component8_1</frameName>
            </plugin>
        </sensor>
    </gazebo>
    <link name="base_link">
        <inertial>
            <origin rpy="0 0 0" xyz="-0.0036570411146029298 9.64624872804682e-17 0.07733171782905483" />
            <mass value="3.198140661088289" />
            <inertia ixx="0.022396" ixy="0.0" ixz="0.000252" iyy="0.025301" iyz="0.0" izz="0.046154" />
        </inertial>
        <visual>
            <origin rpy="0 0 0" xyz="0 0 0" />
            <geometry>
                <mesh filename="package://finaldesign_description/meshes/base_link.stl" scale="0.001 0.001 0.001" />
            </geometry>
            <material name="silver" />
        </visual>
        <collision>
            <origin rpy="0 0 0" xyz="0 0 0" />
            <geometry>
                <mesh filename="package://finaldesign_description/meshes/base_link.stl" scale="0.001 0.001 0.001" />
            </geometry>
        </collision>
    </link>
    <link name="right_wheel_1">
        <inertial>
            <origin rpy="0 0 0" xyz="-1.2352049280260327e-17 0.015000000000000013 0.0" />
            <mass value="0.3423845118560751" />
            <inertia ixx="0.00036" ixy="-0.0" ixz="-0.0" iyy="0.000669" iyz="0.0" izz="0.00036" />
        </inertial>
        <visual>
            <origin rpy="0 0 0" xyz="-0.0 -0.15 -0.0625" />
            <geometry>
                <mesh filename="package://finaldesign_description/meshes/right_wheel_1.stl" scale="0.001 0.001 0.001" />
            </geometry>
            <material name="silver" />
        </visual>
        <collision>
            <origin rpy="0 0 0" xyz="-0.0 -0.15 -0.0625" />
            <geometry>
                <mesh filename="package://finaldesign_description/meshes/right_wheel_1.stl" scale="0.001 0.001 0.001" />
            </geometry>
        </collision>
    </link>
    <link name="left_wheel_1">
        <inertial>
            <origin rpy="0 0 0" xyz="-1.2352049280260327e-17 -0.015000000000000013 0.0" />
            <mass value="0.3423845118560751" />
            <inertia ixx="0.00036" ixy="-0.0" ixz="-0.0" iyy="0.000669" iyz="0.0" izz="0.00036" />
        </inertial>
        <visual>
            <origin rpy="0 0 0" xyz="-0.0 0.15 -0.0625" />
            <geometry>
                <mesh filename="package://finaldesign_description/meshes/left_wheel_1.stl" scale="0.001 0.001 0.001" />
            </geometry>
            <material name="silver" />
        </visual>
        <collision>
            <origin rpy="0 0 0" xyz="-0.0 0.15 -0.0625" />
            <geometry>
                <mesh filename="package://finaldesign_description/meshes/left_wheel_1.stl" scale="0.001 0.001 0.001" />
            </geometry>
        </collision>
    </link>
    <link name="Component8_1">
        <inertial>
            <origin rpy="0 0 0" xyz="0.0 0.0 0.009999999999999995" />
            <mass value="0.1348685726186098" />
            <inertia ixx="7.3e-05" ixy="-0.0" ixz="0.0" iyy="7.3e-05" iyz="-0.0" izz="0.000137" />
        </inertial>
        <visual>
            <origin rpy="0 0 0" xyz="0.09 -0.0 -0.1075" />
            <geometry>
                <mesh filename="package://finaldesign_description/meshes/Component8_1.stl" scale="0.001 0.001 0.001" />
            </geometry>
            <material name="silver" />
        </visual>
        <collision>
            <origin rpy="0 0 0" xyz="0.09 -0.0 -0.1075" />
            <geometry>
                <mesh filename="package://finaldesign_description/meshes/Component8_1.stl" scale="0.001 0.001 0.001" />
            </geometry>
        </collision>
    </link>
    <link name="Component2_1">
        <inertial>
            <origin rpy="0 0 0" xyz="0.09194772525892057 0.04 0.024637318729006485" />
            <mass value="0.29750431282622997" />
            <inertia ixx="0.000156" ixy="-0.0" ixz="-0.000332" iyy="0.001374" iyz="0.0" izz="0.001308" />
        </inertial>
        <visual>
            <origin rpy="0 0 0" xyz="-0.0 0.04 -0.1525" />
            <geometry>
                <mesh filename="package://finaldesign_description/meshes/Component2_1.stl" scale="0.001 0.001 0.001" />
            </geometry>
            <material name="silver" />
        </visual>
        <collision>
            <origin rpy="0 0 0" xyz="-0.0 0.04 -0.1525" />
            <geometry>
                <mesh filename="package://finaldesign_description/meshes/Component2_1.stl" scale="0.001 0.001 0.001" />
            </geometry>
        </collision>
    </link>
    <link name="Component3_1">
        <inertial>
            <origin rpy="0 0 0" xyz="0.11210365947142531 0.04935903979651904 0.03077041053487456" />
            <mass value="0.3506940885621103" />
            <inertia ixx="0.001106" ixy="-2.5e-05" ixz="-0.000202" iyy="0.000859" iyz="-7e-06" izz="0.001804" />
        </inertial>
        <visual>
            <origin rpy="0 0 0" xyz="-0.193185 0.02 -0.204264" />
            <geometry>
                <mesh filename="package://finaldesign_description/meshes/Component3_1.stl" scale="0.001 0.001 0.001" />
            </geometry>
            <material name="silver" />
        </visual>
        <collision>
            <origin rpy="0 0 0" xyz="-0.193185 0.02 -0.204264" />
            <geometry>
                <mesh filename="package://finaldesign_description/meshes/Component3_1.stl" scale="0.001 0.001 0.001" />
            </geometry>
        </collision>
    </link>
    <link name="Component6_1">
        <inertial>
            <origin rpy="0 0 0" xyz="0.022341136656001626 0.011310037261532749 0.005986524413508304" />
            <mass value="0.22264448602810621" />
            <inertia ixx="0.000184" ixy="1.3e-05" ixz="-1.7e-05" iyy="0.000405" iyz="3e-06" izz="0.000242" />
        </inertial>
        <visual>
            <origin rpy="0 0 0" xyz="-0.348309 0.08 -0.246578" />
            <geometry>
                <mesh filename="package://finaldesign_description/meshes/Component6_1.stl" scale="0.001 0.001 0.001" />
            </geometry>
            <material name="silver" />
        </visual>
        <collision>
            <origin rpy="0 0 0" xyz="-0.348309 0.08 -0.246578" />
            <geometry>
                <mesh filename="package://finaldesign_description/meshes/Component6_1.stl" scale="0.001 0.001 0.001" />
            </geometry>
        </collision>
    </link>
    <link name="Component7_1">
        <inertial>
            <origin rpy="0 0 0" xyz="0.022341174865850022 -0.011310030365267815 0.005986531564266734" />
            <mass value="0.2226446411216698" />
            <inertia ixx="0.000184" ixy="-1.3e-05" ixz="-1.7e-05" iyy="0.000405" iyz="-3e-06" izz="0.000242" />
        </inertial>
        <visual>
            <origin rpy="0 0 0" xyz="-0.348309 -0.14 -0.246578" />
            <geometry>
                <mesh filename="package://finaldesign_description/meshes/Component7_1.stl" scale="0.001 0.001 0.001" />
            </geometry>
            <material name="silver" />
        </visual>
        <collision>
            <origin rpy="0 0 0" xyz="-0.348309 -0.14 -0.246578" />
            <geometry>
                <mesh filename="package://finaldesign_description/meshes/Component7_1.stl" scale="0.001 0.001 0.001" />
            </geometry>
        </collision>
    </link>
    <joint name="Revolute_1" type="continuous">
        <origin rpy="0 0 0" xyz="0.0 0.15 0.0625" />
        <parent link="base_link" />
        <child link="right_wheel_1" />
        <axis xyz="0.0 1.0 0.0" />
    </joint>
    <joint name="Revolute_2" type="continuous">
        <origin rpy="0 0 0" xyz="0.0 -0.15 0.0625" />
        <parent link="base_link" />
        <child link="left_wheel_1" />
        <axis xyz="0.0 1.0 0.0" />
    </joint>
    <joint name="Rigid_3" type="fixed">
        <origin rpy="0 0 0" xyz="-0.09 0.0 0.1075" />
        <parent link="base_link" />
        <child link="Component8_1" />
    </joint>
    <joint name="Revolute_4" type="revolute">
        <origin rpy="0 0 0" xyz="0.0 -0.04 0.1525" />
        <parent link="base_link" />
        <child link="Component2_1" />
        <axis xyz="0.0 -1.0 0.0" />
        <limit effort="100" lower="0.261799" upper="2.96706" velocity="100" />
    </joint>
    <joint name="Revolute_7" type="revolute">
        <origin rpy="0 0 0" xyz="0.193185 0.02 0.051764" />
        <parent link="Component2_1" />
        <child link="Component3_1" />
        <axis xyz="0.0 1.0 0.0" />
        <limit effort="100" lower="0.261799" upper="2.96706" velocity="100" />
    </joint>
    <joint name="Slider_8" type="prismatic">
        <origin rpy="0 0 0" xyz="0.155124 -0.06 0.042314" />
        <parent link="Component3_1" />
        <child link="Component6_1" />
        <axis xyz="0.0 -1.0 0.0" />
        <limit effort="100" lower="-0.06" upper="0.0" velocity="100" />
    </joint>
    <joint name="Slider_9" type="prismatic">
        <origin rpy="0 0 0" xyz="0.155124 0.16 0.042314" />
        <parent link="Component3_1" />
        <child link="Component7_1" />
        <axis xyz="0.0 1.0 0.0" />
        <limit effort="100" lower="-0.06" upper="0.0" velocity="100" />
    </joint>
</robot>

